Workbook

Sheet 🏠 Início
A1: APOSTOLADO DA ORAÇÃO – Nova Odessa, SP
A2: Paróquia São Jorge · Diocese de Limeira
A3: Comunidades: Santa Luzia · Santa Dulce dos Pobres · N. Sra. de Fátima
A5: Atualizado em: | B5: =HOJE()
A7: Resumo do Apostolado
A8: Total de Membros | B8: =CONT.NÚM('📋 Membros'!A:A)-1
A9: Ativos | B9: =CONT.SE('📋 Membros'!N:N,"Ativo")+CONT.SE('📋 Membros'!N:N,"Ativo (presumido)")
A10: Inativos | B10: =CONT.SE('📋 Membros'!N:N,"Inativo")
A11: Desistentes | B11: =CONT.SE('📋 Membros'!N:N,"Desistente")
A12: Falecidos | B12: =CONT.SE('📋 Membros'!N:N,"Falecida")
A13: Consagrados | B13: =CONT.SE('📋 Membros'!O:O,"Sim")
A15: Próximos aniversários: veja a aba 🎂 Aniversários
A17: Navegação rápida:
A18: "Que o Sagrado Coração de Jesus reine em nossos lares e em nossa comunidade."
A20: 📊 Relatórios | B20: 📜 Memorial | C20: ⚙️ Configurações | D20: 📝 Instruções

Sheet 📋 Membros
A1: ID | B1: Nº Livro | C1: Nome Completo | D1: Sexo | E1: Data Nasc. | F1: Idade | G1: Data Ingresso | H1: Tempo Apostolado (anos) | I1: Endereço | J1: Bairro | K1: Cidade | L1: Telefone | M1: Função Pastoral | N1: Situação | O1: Consagrada? | P1: Data Consagração | Q1: Observações | R1: Página do Livro
A2: 1 | B2: 1 | C2: Alice Euzébio Pereira | D2: F | E2: 21514 | F2: =SE(E2<>"",DATADIF(E2,HOJE(),"Y"),"") | H2: =SE(G2<>"",DATADIF(G2,HOJE(),"Y"),"") | I2: Rua João Batista de Almeida, 47 | J2: Nova Odessa | K2: Nova Odessa | L2: (19) 99131-5952 | N2: Inativo | O2: Não | Q2: Não é membro ativo na comunidade. | R2: p.6
A3: 2 | B3: 2 | C3: Ana Borges | D3: F | E3: 15613 | F3: =SE(E3<>"",DATADIF(E3,HOJE(),"Y"),"") | H3: =SE(G3<>"",DATADIF(G3,HOJE(),"Y"),"") | K3: Nova Odessa | N3: Ativo | O3: Não | Q3: Registro mínimo – somente nome e aniversário. | R3: p.6
A4: 3 | B4: 3 | C4: Aparecida Petri | D4: F | E4: 20474 | F4: =SE(E4<>"",DATADIF(E4,HOJE(),"Y"),"") | H4: =SE(G4<>"",DATADIF(G4,HOJE(),"Y"),"") | I4: Rua Sebastião Cardoso, s/n | J4: Nova Odessa | K4: Nova Odessa | L4: (19) 99389-6167 | N4: Ativo | O4: Não | R4: p.6
A5: 4 | B5: 4 | C5: Argemira dos Santos (Mirinha) | D5: F | E5: 18837 | F5: =SE(E5<>"",DATADIF(E5,HOJE(),"Y"),"") | G5: 42923 | H5: =SE(G5<>"",DATADIF(G5,HOJE(),"Y"),"") | I5: Rua da Paz, 261 | J5: Terranova | K5: Nova Odessa | L5: (19) 99186-4603 | N5: Ativo | O5: Não | Q5: Paróquia Sta. Luzia – Pe. Luiz Antônio. | R5: p.6
A6: 5 | B6: 5 | C6: Antônio | D6: M | E6: 16398 | F6: =SE(E6<>"",DATADIF(E6,HOJE(),"Y"),"") | H6: =SE(G6<>"",DATADIF(G6,HOJE(),"Y"),"") | K6: Nova Odessa | N6: Ativo | O6: Não | Q6: Sobrenome não registrado no livro. | R6: p.6
A7: 6 | B7: 6 | C7: Cacilda Batista Degan | D7: F | E7: 14469 | F7: =SE(E7<>"",DATADIF(E7,HOJE(),"Y"),"") | G7: 41640 | H7: =SE(G7<>"",DATADIF(G7,HOJE(),"Y"),"") | I7: Alameda do Saber, 23 | J7: Jd. Fibra | K7: Nova Odessa | L7: (19) 99755-???? | N7: Ativo | O7: Não | Q7: Comunidade de Santa Luzia desde 2014. | R7: p.6
A8: 8 | B8: 8 | C8: Célia Aparecida | D8: F | E8: 26113 | F8: =SE(E8<>"",DATADIF(E8,HOJE(),"Y"),"") | H8: =SE(G8<>"",DATADIF(G8,HOJE(),"Y"),"") | K8: Nova Odessa | N8: Ativo | O8: Não | Q8: Nº 7 ausente entre Cacilda e Célia. | R8: p.6
A9: 9 | B9: 9 | C9: Graziela Ellen Santos | D9: F | E9: 29228 | F9: =SE(E9<>"",DATADIF(E9,HOJE(),"Y"),"") | G9: 42923 | H9: =SE(G9<>"",DATADIF(G9,HOJE(),"Y"),"") | I9: Rua Jordano Milani, 142 | J9: N. Sra. de Fátima | K9: Nova Odessa | L9: (19) 98147-46?? | N9: Ativo | O9: Não | Q9: Paróquia Sta. Luzia – Pe. Luís Antônio. | R9: p.6b
A10: 10 | B10: 10 | C10: Lucas Gaveta Silva | D10: M | E10: 30925 | F10: =SE(E10<>"",DATADIF(E10,HOJE(),"Y"),"") | G10: 42923 | H10: =SE(G10<>"",DATADIF(G10,HOJE(),"Y"),"") | I10: Rua Jordano Milani, 142 | J10: N. Sra. de Fátima | K10: Nova Odessa | L10: (19) 98129-1150 | N10: Ativo | O10: Não | Q10: Paróquia de Santa Luzia. | R10: p.6b
A11: 11 | B11: 11 | C11: Claudionice Batista Fernandes (Sau) | D11: F | E11: 26397 | F11: =SE(E11<>"",DATADIF(E11,HOJE(),"Y"),"") | H11: =SE(G11<>"",DATADIF(G11,HOJE(),"Y"),"") | I11: Rua Maximiliano Dal Medico, 290 | J11: Santa Luíza II | K11: Nova Odessa | L11: (19) 99528-3553 | M11: Catequista | N11: Ativo | O11: Não | Q11: Apelido: Sau. Comunidade Santa Luzia. | R11: p.6b
A12: 12 | B12: 12 | C12: Gleide | D12: F | E12: 19316 | F12: =SE(E12<>"",DATADIF(E12,HOJE(),"Y"),"") | H12: =SE(G12<>"",DATADIF(G12,HOJE(),"Y"),"") | I12: Rua Antônio Pereira Freire, 05 | J12: Nova Odessa | K12: Nova Odessa | L12: (19) 99313-9345 | M12: Ministra da Eucaristia (até 2019) / Liturgia | N12: Ativo | O12: Não | Q12: Atuou na Ministra da Eucaristia até 2019; hoje na Liturgia. | R12: p.6b
A13: 13 | B13: 13 | C13: Devanira Vitta Lobão | D13: F | E13: 17458 | F13: =SE(E13<>"",DATADIF(E13,HOJE(),"Y"),"") | H13: =SE(G13<>"",DATADIF(G13,HOJE(),"Y"),"") | I13: Rua das Crianças, 1162 | J13: N. Sra. de Fátima | K13: Nova Odessa | L13: (19) 99491-9890 | N13: Ativo | O13: Não | R13: p.6b
A14: 14 | B14: 14 | C14: Eneide Bernardes Grandini | D14: F | E14: 13329 | F14: =SE(E14<>"",DATADIF(E14,HOJE(),"Y"),"") | G14: 20090 | H14: =SE(G14<>"",DATADIF(G14,HOJE(),"Y"),"") | I14: Rua Frederico Lanzoni, 55 | J14: Santa Luíza II | K14: Nova Odessa | L14: (19) 3466-0924 | M14: Pastoral dos Doentes / Ministra da Eucaristia | N14: Ativo | O14: Não | Q14: MEMBRO MAIS ANTIGO. Ingresso 1955 em Piracicaba; Nova Odessa desde 2000. | R14: p.6b
A15: 15 | B15: 15 | C15: Ione Michelan da Silva | D15: F | E15: 23922 | F15: =SE(E15<>"",DATADIF(E15,HOJE(),"Y"),"") | H15: =SE(G15<>"",DATADIF(G15,HOJE(),"Y"),"") | I15: Rua Sebastião da Cruz Mata, 25 | J15: Triunfo | K15: Nova Odessa | L15: (19) 99320-4021 | N15: Inativo | O15: Não | Q15: Inativo na comunidade. | R15: p.7
A16: 16 | B16: 16 | C16: Fátima Aparecida Felix Carmossi | D16: F | E16: 22647 | F16: =SE(E16<>"",DATADIF(E16,HOJE(),"Y"),"") | H16: =SE(G16<>"",DATADIF(G16,HOJE(),"Y"),"") | I16: Rua João Batista de Almeida, 16 | J16: Triunfo | K16: Nova Odessa | L16: (19) 99384-5059 | M16: Ministra da Eucaristia | N16: Ativo | O16: Não | Q16: Comunidade Sta. Luzia / Irmã Joyce. | R16: p.7
A17: 17 | B17: 17 | C17: Helena Rosante (Helena de Fátima Rosante Caetano) | D17: F | E17: 24607 | F17: =SE(E17<>"",DATADIF(E17,HOJE(),"Y"),"") | H17: =SE(G17<>"",DATADIF(G17,HOJE(),"Y"),"") | I17: Rua das Crianças, 1161 | J17: N. Sra. de Fátima | K17: Nova Odessa | L17: (19) 99280-8069 | N17: Ativo | O17: Não | Q17: Esposa de Osmar Caetano (#38). Verificar duplicidade com Helena (#45). | R17: p.7
A18: 18 | B18: 18 | C18: Sair Rosante | D18: M | F18: =SE(E18<>"",DATADIF(E18,HOJE(),"Y"),"") | H18: =SE(G18<>"",DATADIF(G18,HOJE(),"Y"),"") | I18: Rua Jordano Milani, 158 | J18: N. Sra. de Fátima | K18: Nova Odessa | L18: (19) 99289-5207 | N18: Ativo | O18: Não | Q18: Irmão de Helena Rosante (#17). Aniversário não preenchido. | R18: p.7
A19: 19 | B19: 19 | C19: Jefferson Ap. Rosante Caetano | D19: M | E19: 37124 | F19: =SE(E19<>"",DATADIF(E19,HOJE(),"Y"),"") | H19: =SE(G19<>"",DATADIF(G19,HOJE(),"Y"),"") | I19: Rua das Crianças, 1164 | J19: N. Sra. de Fátima | K19: Nova Odessa | L19: (19) 99898-9562 | N19: Ativo | O19: Não | Q19: Possível filho de Helena (#17) e Osmar Caetano (#38). | R19: p.7
A20: 20 | B20: 20 | C20: Jeanete Batista da Silva | D20: F | E20: 23732 | F20: =SE(E20<>"",DATADIF(E20,HOJE(),"Y"),"") | H20: =SE(G20<>"",DATADIF(G20,HOJE(),"Y"),"") | I20: Rua Antônio Pereira Freire, 08 | J20: Triunfo | K20: Nova Odessa | L20: (19) 98158-3742 | M20: Catequese (Coordenadora) / Terço | N20: Ativo | O20: Não | Q20: Pastoral Catequese – Coordenadora; Pastoral do Terço. | R20: p.7
A21: 21 | B21: 21 | C21: Karen | D21: F | E21: 38237 | F21: =SE(E21<>"",DATADIF(E21,HOJE(),"Y"),"") | H21: =SE(G21<>"",DATADIF(G21,HOJE(),"Y"),"") | I21: Rua Maximiliano Dal Medico, s/n | J21: Santa Luíza II | K21: Nova Odessa | N21: Ativo | O21: Não | Q21: Sobrenome não registrado. | R21: p.7b
A22: 22 | B22: 22 | C22: Renata Cristina Rodrigues Scardovelli | D22: F | E22: 27417 | F22: =SE(E22<>"",DATADIF(E22,HOJE(),"Y"),"") | H22: =SE(G22<>"",DATADIF(G22,HOJE(),"Y"),"") | I22: Rua Maximiliano Dal Medico, 774 | J22: Santa Luíza II | K22: Nova Odessa | L22: (19) 99214-6855 | N22: Ativo | O22: Não | R22: p.7b
A23: 23 | B23: 23 | C23: Lázaro Manoel da Silva Neto | D23: M | E23: 22370 | F23: =SE(E23<>"",DATADIF(E23,HOJE(),"Y"),"") | H23: =SE(G23<>"",DATADIF(G23,HOJE(),"Y"),"") | I23: Rua Antônio Pereira Freire, 09 | J23: Triunfo | K23: Nova Odessa | N23: Ativo | O23: Não | Q23: Telefone não preenchido. | R23: p.7b
A24: 24 | B24: 24 | C24: Luiz Antônio | D24: M | E24: 23281 | F24: =SE(E24<>"",DATADIF(E24,HOJE(),"Y"),"") | H24: =SE(G24<>"",DATADIF(G24,HOJE(),"Y"),"") | I24: Rua Joaquim Leite da Cunha, 1088 | J24: Triunfo | K24: Nova Odessa | L24: (19) 99478-8717 | M24: Coordenador do Apostolado / Ministro da Eucaristia | N24: Ativo | O24: Não | Q24: Coordenador do Apostolado da Oração. | R24: p.7b
A25: 25 | B25: 25 | C25: Iara | D25: F | F25: =SE(E25<>"",DATADIF(E25,HOJE(),"Y"),"") | H25: =SE(G25<>"",DATADIF(G25,HOJE(),"Y"),"") | I25: Rua Joaquim Leite da Cunha, 1088 | J25: Triunfo | K25: Nova Odessa | N25: Ativo | O25: Não | Q25: Aniversário: 23/12, ano ilegível. Possível esposa de Luiz Antônio (#24). | R25: p.7b
A26: 26 | B26: 26 | C26: Teresa | D26: F | E26: 26834 | F26: =SE(E26<>"",DATADIF(E26,HOJE(),"Y"),"") | H26: =SE(G26<>"",DATADIF(G26,HOJE(),"Y"),"") | K26: Nova Odessa | N26: Falecida | O26: Não | Q26: Faleceu – data não registrada. | R26: p.7b
A27: 27 | B27: 27 | C27: Luíza Regina | D27: F | E27: 22709 | F27: =SE(E27<>"",DATADIF(E27,HOJE(),"Y"),"") | H27: =SE(G27<>"",DATADIF(G27,HOJE(),"Y"),"") | K27: Nova Odessa | M27: Coordenadora do Apostolado | N27: Ativo | O27: Não | Q27: Endereço e telefone não preenchidos. | R27: p.8
A28: 28 | B28: 28 | C28: Luíza Marrick | D28: F | E28: 15578 | F28: =SE(E28<>"",DATADIF(E28,HOJE(),"Y"),"") | H28: =SE(G28<>"",DATADIF(G28,HOJE(),"Y"),"") | K28: Nova Odessa | L28: (19) 3486-1575 | N28: Falecida | O28: Não | Q28: Faleceu – data não registrada. | R28: p.8
A29: 29 | B29: 29 | C29: Leonice | D29: F | E29: 16414 | F29: =SE(E29<>"",DATADIF(E29,HOJE(),"Y"),"") | H29: =SE(G29<>"",DATADIF(G29,HOJE(),"Y"),"") | K29: Nova Odessa | N29: Falecida | O29: Não | Q29: Sobrenome não registrado. Faleceu. | R29: p.8
A30: 30 | B30: 30 | C30: Maria José | D30: F | F30: =SE(E30<>"",DATADIF(E30,HOJE(),"Y"),"") | H30: =SE(G30<>"",DATADIF(G30,HOJE(),"Y"),"") | K30: Nova Odessa | N30: Ativo | O30: Não | Q30: Aniversário: 08/06, ano ilegível. | R30: p.8
A31: 31 | B31: 31 | C31: Maria de Lourdes | D31: F | E31: 15781 | F31: =SE(E31<>"",DATADIF(E31,HOJE(),"Y"),"") | H31: =SE(G31<>"",DATADIF(G31,HOJE(),"Y"),"") | K31: Nova Odessa | N31: Falecida | O31: Não | Q31: Faleceu – data não registrada. | R31: p.8
A32: 32 | B32: 32 | C32: Rosa Pigato | D32: F | F32: =SE(E32<>"",DATADIF(E32,HOJE(),"Y"),"") | H32: =SE(G32<>"",DATADIF(G32,HOJE(),"Y"),"") | K32: Nova Odessa | N32: Falecida | O32: Não | Q32: Aniversário: 15/02, ano ilegível. Faleceu. | R32: p.8
A33: 33 | B33: 33 | C33: Maria Soares | D33: F | F33: =SE(E33<>"",DATADIF(E33,HOJE(),"Y"),"") | H33: =SE(G33<>"",DATADIF(G33,HOJE(),"Y"),"") | K33: Nova Odessa | N33: Falecida | O33: Não | Q33: Aniversário completamente ilegível. Faleceu. | R33: p.8b
A34: 34 | B34: 34 | C34: Nair Leal Damas | D34: F | E34: 14437 | F34: =SE(E34<>"",DATADIF(E34,HOJE(),"Y"),"") | G34: 26665 | H34: =SE(G34<>"",DATADIF(G34,HOJE(),"Y"),"") | I34: Rua Dirceu Joc Boscori, 26 | J34: Santa Luíza I | K34: Nova Odessa | N34: Ativo | O34: Não | Q34: Participa do Apostolado desde 1973. | R34: p.8b
A35: 35 | B35: 35 | C35: Neuza Rafa | D35: F | E35: 20511 | F35: =SE(E35<>"",DATADIF(E35,HOJE(),"Y"),"") | H35: =SE(G35<>"",DATADIF(G35,HOJE(),"Y"),"") | K35: Nova Odessa | N35: Ativo | O35: Não | Q35: Sobrenome 'Rafa' pode ser abreviação. | R35: p.8b
A36: 36 | B36: 36 | C36: Natália | D36: F | E36: 18257 | F36: =SE(E36<>"",DATADIF(E36,HOJE(),"Y"),"") | H36: =SE(G36<>"",DATADIF(G36,HOJE(),"Y"),"") | I36: Rua Aristides Benedito, 11 | J36: Triunfo | K36: Nova Odessa | L36: (19) 99296-37?? | N36: Ativo | O36: Não | Q36: Sobrenome não registrado. | R36: p.8b
A37: 37 | B37: 37 | C37: Olímpia Straiotto Garcia | D37: F | E37: 14324 | F37: =SE(E37<>"",DATADIF(E37,HOJE(),"Y"),"") | H37: =SE(G37<>"",DATADIF(G37,HOJE(),"Y"),"") | K37: Nova Odessa | M37: Coordenadora Apostolado – Comunidade Santa Luzia | N37: Falecida | O37: Não | Q37: FALECEU EM 15/04/2024. | R37: p.8b
A38: 38 | B38: 38 | C38: Osmar Caetano | D38: M | E38: 22738 | F38: =SE(E38<>"",DATADIF(E38,HOJE(),"Y"),"") | H38: =SE(G38<>"",DATADIF(G38,HOJE(),"Y"),"") | I38: Rua das Crianças, 1164 | J38: N. Sra. de Fátima | K38: Nova Odessa | N38: Ativo | O38: Não | Q38: Marido de Helena Rosante (#17). | R38: p.8b
A39: 39 | B39: 39 | C39: Pedro | D39: M | E39: 36559 | F39: =SE(E39<>"",DATADIF(E39,HOJE(),"Y"),"") | H39: =SE(G39<>"",DATADIF(G39,HOJE(),"Y"),"") | K39: Nova Odessa | N39: Ativo | O39: Não | Q39: Registro fragmentado entre páginas 8b e 9. | R39: p.8b/9
A40: 40 | B40: 40 | C40: Osinete Aparecida dos Santos | D40: F | E40: 28725 | F40: =SE(E40<>"",DATADIF(E40,HOJE(),"Y"),"") | H40: =SE(G40<>"",DATADIF(G40,HOJE(),"Y"),"") | I40: Rua da Amizade, 282 | J40: Terranova | K40: Nova Odessa | L40: (19) 99825-5018 | N40: Ativo | O40: Não | Q40: Filha de Santa Luzia. | R40: p.9
...

Sheet 🗺️ Rota de Visitas
A1: Rota de Visitas Domiciliares – Apostolado da Oração
A2: Rota sugerida por bairro. Marque 'S' na coluna Entregue? após cada entrega. Ore um Pai-Nosso antes de cada visita. (São Josemaría Escrivá)
A4: Ordem | B4: Nome | C4: Endereço Completo | D4: Bairro | E4: Telefone | F4: Situação | G4: Item a Entregar | H4: Entregue? | I4: Data da Visita | J4: Observações da Visita
A5: ── BAIRRO: RESIDENCIAL SANTA LUÍZA II ──
A6: 1 | B6: Carlos José Amorim Nobuyasu | C6: Rua Frederico Lanzoni, 181, Residencial Santa Luíza II, Nova Odessa | D6: Residencial Santa Luíza II | E6: (19) 98845-5763 | F6: Ativo
A7: ── BAIRRO: SANTA LUÍZA I ──
A8: 2 | B8: Nair Leal Damas | C8: Rua Dirceu Joc Boscori, 26, Santa Luíza I, Nova Odessa | D8: Santa Luíza I | F8: Ativo
A9: ── BAIRRO: SANTA LUÍZA II ──
A10: 3 | B10: Eneide Bernardes Grandini | C10: Rua Frederico Lanzoni, 55, Santa Luíza II, Nova Odessa | D10: Santa Luíza II | E10: (19) 3466-0924 | F10: Ativo
A11: ── BAIRRO: SANTA LUÍZA I ──
A12: 4 | B12: Valdomira Marestoni (D. Nena) | C12: Rua Antônio Dorto Sobrinho, 89, Santa Luíza I, Nova Odessa | D12: Santa Luíza I | E12: (19) 99373-1760 | F12: Ativo
A13: ── BAIRRO: SANTA LUÍZA II ──
A14: 5 | B14: Rosangela Alves Amorim de Oliveira | C14: Rua Frederico Lanzoni, 191, Santa Luíza II, Nova Odessa | D14: Santa Luíza II | F14: Ativo
A15: 6 | B15: Claudionice Batista Fernandes (Sau) | C15: Rua Maximiliano Dal Medico, 290, Santa Luíza II, Nova Odessa | D15: Santa Luíza II | E15: (19) 99528-3553 | F15: Ativo
A16: ── BAIRRO: SANTA LUÍZA I ──
A17: 7 | B17: Irene Rosineia de Abreu Pedrao | C17: Rua Ângelo Diconi, 471, Santa Luíza I, Nova Odessa | D17: Santa Luíza I | E17: (19) 99394-4579 | F17: Ativo
A18: 8 | B18: Vera Lucia de Abreu Lobão | C18: Rua Ângelo Piconi, 471, Santa Luíza I, Nova Odessa | D18: Santa Luíza I | E18: (19) 99399-4599 | F18: Ativo
A19: ── BAIRRO: SANTA LUÍZA II ──
A20: 9 | B20: Renata Cristina Rodrigues Scardovelli | C20: Rua Maximiliano Dal Medico, 774, Santa Luíza II, Nova Odessa | D20: Santa Luíza II | E20: (19) 99214-6855 | F20: Ativo
A21: ── BAIRRO: SANTA LUÍZA I ──
A22: 10 | B22: Eliane Francisca dos Santos | C22: Rua Joaquim Leite da Cunha, 901, Santa Luíza I, Nova Odessa | D22: Santa Luíza I | E22: (11) 99304-0675 | F22: Ativo
A23: ── BAIRRO: SANTA LUÍZA II ──
A24: 11 | B24: Karen | C24: Rua Maximiliano Dal Medico, s/n, Santa Luíza II, Nova Odessa | D24: Santa Luíza II | F24: Ativo
A25: ── BAIRRO: N. SRA. DE FÁTIMA ──
A26: 12 | B26: Graziela Ellen Santos | C26: Rua Jordano Milani, 142, N. Sra. de Fátima, Nova Odessa | D26: N. Sra. de Fátima | E26: (19) 98147-46?? | F26: Ativo
A27: 13 | B27: Lucas Gaveta Silva | C27: Rua Jordano Milani, 142, N. Sra. de Fátima, Nova Odessa | D27: N. Sra. de Fátima | E27: (19) 98129-1150 | F27: Ativo
A28: 14 | B28: Sair Rosante | C28: Rua Jordano Milani, 158, N. Sra. de Fátima, Nova Odessa | D28: N. Sra. de Fátima | E28: (19) 99289-5207 | F28: Ativo
A29: 15 | B29: Helena Rosante (Helena de Fátima Rosante Caetano) | C29: Rua das Crianças, 1161, N. Sra. de Fátima, Nova Odessa | D29: N. Sra. de Fátima | E29: (19) 99280-8069 | F29: Ativo
A30: 16 | B30: Devanira Vitta Lobão | C30: Rua das Crianças, 1162, N. Sra. de Fátima, Nova Odessa | D30: N. Sra. de Fátima | E30: (19) 99491-9890 | F30: Ativo
A31: 17 | B31: Jefferson Ap. Rosante Caetano | C31: Rua das Crianças, 1164, N. Sra. de Fátima, Nova Odessa | D31: N. Sra. de Fátima | E31: (19) 99898-9562 | F31: Ativo
A32: 18 | B32: Osmar Caetano | C32: Rua das Crianças, 1164, N. Sra. de Fátima, Nova Odessa | D32: N. Sra. de Fátima | F32: Ativo
A33: ── BAIRRO: TRIUNFO ──
A34: 19 | B34: Jeanete Batista da Silva | C34: Rua Antônio Pereira Freire, 08, Triunfo, Nova Odessa | D34: Triunfo | E34: (19) 98158-3742 | F34: Ativo
A35: 20 | B35: Lázaro Manoel da Silva Neto | C35: Rua Antônio Pereira Freire, 09, Triunfo, Nova Odessa | D35: Triunfo | F35: Ativo
A36: 21 | B36: Natália | C36: Rua Aristides Benedito, 11, Triunfo, Nova Odessa | D36: Triunfo | E36: (19) 99296-37?? | F36: Ativo
A37: 22 | B37: Fátima Aparecida Felix Carmossi | C37: Rua João Batista de Almeida, 16, Triunfo, Nova Odessa | D37: Triunfo | E37: (19) 99384-5059 | F37: Ativo
A38: 23 | B38: Eurípia Aparecida Rafael Frizoni | C38: Rua João Batista de Almeida, 24, Triunfo, Nova Odessa | D38: Triunfo | E38: (19) 99612-0246 | F38: Ativo
A39: 24 | B39: Simone Aparecida Frizoni | C39: Rua João Batista de Almeida, 24, Triunfo, Nova Odessa | D39: Triunfo | E39: (19) 99287-6936 | F39: Ativo
A40: 25 | B40: Luiz Ferreira de Paula | C40: Rua Professor Antônio F. Gonçalves, 31, Triunfo, Nova Odessa | D40: Triunfo | E40: (11) 98740-5105 | F40: Ativo
A41: 26 | B41: Isabel Ferreira Lopes (Izabel) | C41: Rua João Batista de Almeida, 43, Triunfo, Nova Odessa | D41: Triunfo | E41: (19) 99806-9342 | F41: Ativo
...

Sheet 🎂 Aniversários
A1: Calendário de Aniversários
A2: Uma ligação no dia do aniversário é apostolado de proximidade. São Josemaría: 'Uma atenção oportuna é apostolado.'
A4: Nº | B4: Nome | C4: Data Nasc. | D4: Telefone | E4: Situação | F4: Mês | G4: Dia
A5: 16 | B5: Fátima Aparecida Felix Carmossi | C5: 22647 | D5: (19) 99384-5059 | E5: Ativo | F5: =MÊS(C5) | G5: =DIA(C5)
A6: 9 | B6: Graziela Ellen Santos | C6: 29228 | D6: (19) 98147-46?? | E6: Ativo | F6: =MÊS(C6) | G6: =DIA(C6)
A7: 3 | B7: Aparecida Petri | C7: 20474 | D7: (19) 99389-6167 | E7: Ativo | F7: =MÊS(C7) | G7: =DIA(C7)
A8: 22 | B8: Renata Cristina Rodrigues Scardovelli | C8: 27417 | D8: (19) 99214-6855 | E8: Ativo | F8: =MÊS(C8) | G8: =DIA(C8)
A9: 39 | B9: Pedro | C9: 36559 | E9: Ativo | F9: =MÊS(C9) | G9: =DIA(C9)
A10: 53 | B10: Leila Barbosa Fonseca | C10: 24144 | D10: (19) 99466-2608 | E10: Ativo | F10: =MÊS(C10) | G10: =DIA(C10)
A11: 35 | B11: Neuza Rafa | C11: 20511 | E11: Ativo | F11: =MÊS(C11) | G11: =DIA(C11)
A12: 27 | B12: Luíza Regina | C12: 22709 | E12: Ativo | F12: =MÊS(C12) | G12: =DIA(C12)
A13: 23 | B13: Lázaro Manoel da Silva Neto | C13: 22370 | E13: Ativo | F13: =MÊS(C13) | G13: =DIA(C13)
A14: 38 | B14: Osmar Caetano | C14: 22738 | E14: Ativo | F14: =MÊS(C14) | G14: =DIA(C14)
A15: 11 | B15: Claudionice Batista Fernandes (Sau) | C15: 26397 | D15: (19) 99528-3553 | E15: Ativo | F15: =MÊS(C15) | G15: =DIA(C15)
A16: 41 | B16: Odete | C16: 17644 | E16: Ativo | F16: =MÊS(C16) | G16: =DIA(C16)
A17: 46 | B17: Isabel Ferreira Lopes (Izabel) | C17: 23132 | D17: (19) 99806-9342 | E17: Ativo | F17: =MÊS(C17) | G17: =DIA(C17)
A18: 17 | B18: Helena Rosante (Helena de Fátima Rosante Caetano) | C18: 24607 | D18: (19) 99280-8069 | E18: Ativo | F18: =MÊS(C18) | G18: =DIA(C18)
A19: 42 | B19: Simone Aparecida Frizoni | C19: 32284 | D19: (19) 99287-6936 | E19: Ativo | F19: =MÊS(C19) | G19: =DIA(C19)
A20: 48 | B20: Rosangela Alves Amorim de Oliveira | C20: 26818 | E20: Ativo | F20: =MÊS(C20) | G20: =DIA(C20)
A21: 54 | B21: Maria Neusa Pessoa Pavan | C21: 24273 | D21: (19) 99408-5202 | E21: Desistente | F21: =MÊS(C21) | G21: =DIA(C21)
A22: 14 | B22: Eneide Bernardes Grandini | C22: 13329 | D22: (19) 3466-0924 | E22: Ativo | F22: =MÊS(C22) | G22: =DIA(C22)
A23: 8 | B23: Célia Aparecida | C23: 26113 | E23: Ativo | F23: =MÊS(C23) | G23: =DIA(C23)
A24: 15 | B24: Ione Michelan da Silva | C24: 23922 | D24: (19) 99320-4021 | E24: Inativo | F24: =MÊS(C24) | G24: =DIA(C24)
A25: 56 | B25: Vera Lucia de Abreu Lobão | C25: 28310 | D25: (19) 99399-4599 | E25: Ativo | F25: =MÊS(C25) | G25: =DIA(C25)
A26: C2 | B26: Irene Rosineia de Abreu Pedrao | C26: 28310 | D26: (19) 99394-4579 | E26: Ativo | F26: =MÊS(C26) | G26: =DIA(C26)
A27: 34 | B27: Nair Leal Damas | C27: 14437 | E27: Ativo | F27: =MÊS(C27) | G27: =DIA(C27)
A28: 55 | B28: Eliane Francisca dos Santos | C28: 20285 | D28: (11) 99304-0675 | E28: Ativo | F28: =MÊS(C28) | G28: =DIA(C28)
A29: 4 | B29: Argemira dos Santos (Mirinha) | C29: 18837 | D29: (19) 99186-4603 | E29: Ativo | F29: =MÊS(C29) | G29: =DIA(C29)
A30: 52 | B30: Carlos José Amorim Nobuyasu | C30: 37474 | D30: (19) 98845-5763 | E30: Ativo | F30: =MÊS(C30) | G30: =DIA(C30)
A31: 6 | B31: Cacilda Batista Degan | C31: 14469 | D31: (19) 99755-???? | E31: Ativo | F31: =MÊS(C31) | G31: =DIA(C31)
A32: 19 | B32: Jefferson Ap. Rosante Caetano | C32: 37124 | D32: (19) 99898-9562 | E32: Ativo | F32: =MÊS(C32) | G32: =DIA(C32)
A33: 43 | B33: Eurípia Aparecida Rafael Frizoni | C33: 19228 | D33: (19) 99612-0246 | E33: Ativo | F33: =MÊS(C33) | G33: =DIA(C33)
A34: 40 | B34: Osinete Aparecida dos Santos | C34: 28725 | D34: (19) 99825-5018 | E34: Ativo | F34: =MÊS(C34) | G34: =DIA(C34)
A35: 10 | B35: Lucas Gaveta Silva | C35: 30925 | D35: (19) 98129-1150 | E35: Ativo | F35: =MÊS(C35) | G35: =DIA(C35)
A36: 21 | B36: Karen | C36: 38237 | E36: Ativo | F36: =MÊS(C36) | G36: =DIA(C36)
A37: 44 | B37: Valdomira Marestoni (D. Nena) | C37: 16694 | D37: (19) 99373-1760 | E37: Ativo | F37: =MÊS(C37) | G37: =DIA(C37)
A38: 24 | B38: Luiz Antônio | C38: 23281 | D38: (19) 99478-8717 | E38: Ativo | F38: =MÊS(C38) | G38: =DIA(C38)
A39: 2 | B39: Ana Borges | C39: 15613 | E39: Ativo | F39: =MÊS(C39) | G39: =DIA(C39)
A40: 13 | B40: Devanira Vitta Lobão | C40: 17458 | D40: (19) 99491-9890 | E40: Ativo | F40: =MÊS(C40) | G40: =DIA(C40)
A41: 49 | B41: Marlene Degan Fabro | C41: 21480 | D41: (19) 99765-890? | E41: Ativo | F41: =MÊS(C41) | G41: =DIA(C41)
...

Sheet ✝️ Consagrações
A1: Membros Consagrados ao Sagrado Coração de Jesus
A3: ID | B3: Nº | C3: Nome | D3: Data Consagração | E3: Data Ingresso | F3: Bairro | G3: Telefone | H3: Função
A4: 54 | B4: 54 | C4: Maria Neusa Pessoa Pavan | D4: 46060 | E4: 46060 | F4: Terranova | G4: (19) 99408-5202 | H4: Leiga Voluntária – Comunidade Santa Dulce dos Pobres
A5: 55 | B5: 55 | C5: Eliane Francisca dos Santos | D5: 46166 | E5: 46166 | F5: Santa Luíza I | G5: (11) 99304-0675 | H5: Ministra da Eucaristia (Pastoral dos Doentes) / Coordenadora Comunidade Santa Luzia
A6: 56 | B6: 56 | C6: Vera Lucia de Abreu Lobão | D6: 46164 | E6: 46164 | F6: Santa Luíza I | G6: (19) 99399-4599 | H6: Pastoral do Batismo – Paróquia São Jorge

Sheet 📦 Entregas
A1: Controle de Itens Entregues aos Membros
A2: Registre cada entrega. Use a lista na coluna Item.
A4: ID Membro | B4: Nome | C4: Item | D4: Data Entrega | E4: Entregue por | F4: Observação

Sheet 🙏 Intenções
A1: Intenções de Oração Mensais
A3: Mês/Ano | B3: Intenção do Papa | C3: Intenção da Paróquia | D3: Intenção do Apostolado | E3: Observação
A4: Junho/2026 | B4: Rezemos pelos que sofrem por causa de conflitos armados. | C4: Pelas famílias da nossa paróquia. | D4: Pelos membros do Apostolado e seus familiares. | E4: Intenção inaugural do sistema.

Sheet 📅 Agenda
A1: Agenda Pastoral do Apostolado
A3: Data | B3: Hora | C3: Tipo | D3: Descrição | E3: Local | F3: Presentes | G3: Observação
A4: 46179 | B4: 19h30 | C4: Reunião Mensal | D4: Reunião ordinária do Apostolado da Oração | E4: Salão Paroquial – Paróquia São Jorge

Sheet ⚠️ Inconsistências
A1: Inconsistências – Revisão Pastoral
A2: Cada inconsistência é um convite ao cuidado. Resolva com calma e caridade.
A4: Categoria | B4: Prioridade | C4: Descrição | D4: Ação Sugerida | E4: Resolvida?
A5: Duplicidade potencial | B5: 🔴 Crítica | C5: Helena (#45) sem sobrenome pode ser duplicata de Helena Rosante (#17). | D5: Revisar manualmente: confirmar se #45 é mesma pessoa de #17. | E5: Não
A6: Duplicidade potencial | B6: 🟠 Alta | C6: Vera Lucia (#56) e Irene Pedrao (#102) – mesmo endereço (Rua Ângelo, 471) e mesma data de nascimento (04/07/1977). | D6: Verificar se são a mesma pessoa ou grafia diferente da rua (Piconi × Diconi). | E6: Não
A7: Situação confirmada | B7: 🟠 Alta | C7: Maria Neusa Pessoa Pavan (#54) marcada como DESISTENTE. | D7: Retirar da rota de visitas. Guardar registro histórico. | E7: Não
A8: Aniversário incompleto | B8: 🟠 Alta | C8: Iara (#25) – dia 23/12, ano ilegível. | D8: Solicitar confirmação do ano de nascimento. | E8: Não
A9: Aniversário incompleto | B9: 🟠 Alta | C9: Maria José (#30) – dia/mês 08/06, ano ilegível. | D9: Solicitar confirmação do ano de nascimento. | E9: Não
A10: Aniversário incompleto | B10: 🟠 Alta | C10: Rosa Pigato (#32) – dia/mês 15/02, ano ilegível. Falecida. | D10: Verificar com família. | E10: Não
A11: Aniversário incompleto | B11: 🔴 Crítica | C11: Maria Soares (#33) – aniversário completamente ilegível. Falecida. | D11: Verificar com família. | E11: Não
A12: Falecimento sem data | B12: 🟠 Alta | C12: Teresa (#26), Luíza Marrick (#28), Leonice (#29), Maria de Lourdes (#31), Rosa Pigato (#32), Maria Soares (#33) – datas de falecimento não registradas. | D12: Buscar datas nos registros da Paróquia. | E12: Não
A13: Falecimento confirmado com data | B13: 🔵 Informativa | C13: Olímpia Straiotto Garcia (#37) – faleceu em 15/04/2024. | D13: Registro completo. | E13: Sim
A14: Sobrenome ausente | B14: 🟡 Média | C14: 17 membros sem sobrenome completo. | D14: Atualizar registros quando possível. | E14: Não
A15: Telefone parcialmente ilegível | B15: 🟡 Média | C15: Cacilda(#6), Graziela(#9), Natália(#36), Marlene(#49), Dana(#51) – dígitos ilegíveis. | D15: Solicitar atualização nas próximas visitas. | E15: Não
... A21: Consagração registrada | B21: 🔵 Informativa | C21: Eliane (#55) e Vera Lucia (#56) consagradas em 05/06/2026. | D21: Data oficial registrada na coluna Observações. | E21: Sim

Sheet 📊 Relatórios
A1: Relatórios Pastorais
A2: Atualiza automaticamente quando você edita a aba Membros.
A4: Por Situação
A5: Situação | B5: Quantidade
A6: Ativo | B6: =CONT.SE('📋 Membros'!N:N,"Ativo")
A7: Ativo (presumido) | B7: =CONT.SE('📋 Membros'!N:N,"Ativo (presumido)")
A8: Inativo | B8: =CONT.SE('📋 Membros'!N:N,"Inativo")
A9: Desistente | B9: =CONT.SE('📋 Membros'!N:N,"Desistente")
A10: Falecida | B10: =CONT.SE('📋 Membros'!N:N,"Falecida")
A11: TOTAL | B11: =SOMA(B6:B10)
A13: Consagrados
A14: Total consagrados: | B14: =CONT.SE('📋 Membros'!O:O,"Sim")
A16: Completude do Cadastro
A17: Sem telefone | B17: =CONT.SE('📋 Membros'!L:L,"")
A18: Sem endereço | B18: =CONT.SE('📋 Membros'!I:I,"")
A19: Sem função pastoral | B19: =CONT.SE('📋 Membros'!M:M,"")
A21: Membros Ativos por Bairro
A22: Bairro | B22: Membros Ativos
A23: Jd. Fibra | B23: =CONT.SE('📋 Membros'!J:J,A23)
A24: N. Sra. de Fátima | B24: =CONT.SE('📋 Membros'!J:J,A24)
A25: Nova Odessa | B25: =CONT.SE('📋 Membros'!J:J,A25)
A26: Res. Fibra | B26: =CONT.SE('📋 Membros'!J:J,A26)
A27: Residencial Santa Luíza II | B27: =CONT.SE('📋 Membros'!J:J,A27)
A28: Santa Luíza I | B28: =CONT.SE('📋 Membros'!J:J,A28)
A29: Santa Luíza II | B29: =CONT.SE('📋 Membros'!J:J,A29)
A30: Terranova | B30: =CONT.SE('📋 Membros'!J:J,A30)
A31: Triunfo | B31: =CONT.SE('📋 Membros'!J:J,A31)

Sheet 📜 Memorial
A1: Memorial – Membros Falecidos
A2: Em memória dos que nos precederam no caminho da fé.
A4: Nome | B4: Data Nasc. | C4: Data Falecimento | D4: Observação Pastoral
A5: Teresa | B5: 26834 | C5: data não registrada | D5: #26 – Faleceu – data não registrada
A6: Luíza Marrick | B6: 15578 | C6: data não registrada | D6: #28
A7: Leonice | B7: 16414 | C7: data não registrada | D7: #29 – Sobrenome não registrado
A8: Maria de Lourdes | B8: 15781 | C8: data não registrada | D8: #31
A9: Rosa Pigato | C9: data não registrada | D9: #32 – Aniversário ilegível
A10: Maria Soares | C10: data não registrada | D10: #33 – Aniversário ilegível
A11: Olímpia Straiotto Garcia | B11: 14324 | C11: 45397 | D11: #37 – Coordenadora Apostolado Comunidade Santa Luzia
A13: Descansai em paz. Nossa oração vos acompanha. R.I.P.

Sheet ⚙️ Configurações
A1: Configurações do Sistema
A3: Chave | B3: Valor
A4: paroquia | B4: Paróquia São Jorge
A5: diocese | B5: Diocese de Limeira
A6: cidade | B6: Nova Odessa
A7: estado | B7: SP
A8: coordenador | B8: Luiz Antônio
A9: coordenadora | B9: Luíza Regina
A10: comunidades | B10: Santa Luzia · Santa Dulce dos Pobres · N. Sra. de Fátima
A11: arquivo_excel | B11: apostolado.xlsx
A12: backup_automatico | B12: Sim
A13: dias_backup | B13: 30
A14: tema_cor | B14: #6A1B9A
A15: whatsapp_coordenador
A16: observacoes_sistema | B16: Sistema Apostolado da Oração – Nova Odessa

Sheet 📝 Instruções
A1: COMO USAR ESTE SISTEMA Paróquia São Jorge · Apostolado da Oração · Nova Odessa – SP 1. PARA CONSULTAR UM MEMBRO Clique na aba Membros. Use Ctrl+F para buscar pelo nome. 2. PARA ADICIONAR UM NOVO MEMBRO Vá até a última linha com dados na aba Membros. Preencha cada coluna na linha seguinte. Não apague as fórmulas das colunas Idade e Tempo Apostolado. 3. PARA PLANEJAR UMA VISITA Clique na aba Rota de Visitas. Veja os membros por bairro. Escolha o item a entregar e marque S após cada visita. 4. PARA VER ANIVERSÁRIOS Clique na aba Aniversários. Amarelo = mês atual. Verde = próximos 7 dias. 5. PARA CORRIGIR INCONSISTÊNCIAS Clique na aba Inconsistências. Ao resolver, marque Sim na coluna Resolvida? 6. PARA GUARDAR COM SEGURANÇA Salve uma cópia mensal: Apostolado_Jun2026.xlsx, etc. DÚVIDAS? Procure o coordenador ou a coordenadora do Apostolado. "A ordem no trabalho ordinário é forma excelente de amar a Deus." — São Josemaría Escrivá
